[2021-09-03 12:41:38,594] {taskinstance.py:896} INFO - Dependencies all met for <TaskInstance: cartelis-test.airbyte_sync_source_dest 2021-09-02T00:00:00+00:00 [queued]>
[2021-09-03 12:41:38,657] {taskinstance.py:896} INFO - Dependencies all met for <TaskInstance: cartelis-test.airbyte_sync_source_dest 2021-09-02T00:00:00+00:00 [queued]>
[2021-09-03 12:41:38,657] {taskinstance.py:1087} INFO - 
--------------------------------------------------------------------------------
[2021-09-03 12:41:38,657] {taskinstance.py:1088} INFO - Starting attempt 1 of 2
[2021-09-03 12:41:38,657] {taskinstance.py:1089} INFO - 
--------------------------------------------------------------------------------
[2021-09-03 12:41:38,670] {taskinstance.py:1107} INFO - Executing <Task(AirbyteTriggerSyncOperator): airbyte_sync_source_dest> on 2021-09-02T00:00:00+00:00
[2021-09-03 12:41:38,676] {standard_task_runner.py:52} INFO - Started process 894 to run task
[2021-09-03 12:41:38,692] {standard_task_runner.py:76} INFO - Running: ['***', 'tasks', 'run', 'cartelis-test', 'airbyte_sync_source_dest', '2021-09-02T00:00:00+00:00', '--job-id', '6', '--pool', 'default_pool', '--raw', '--subdir', 'DAGS_FOLDER/test_dag.py', '--cfg-path', '/tmp/tmpp6lowd6d', '--error-file', '/tmp/tmpod8ccb8w']
[2021-09-03 12:41:38,693] {standard_task_runner.py:77} INFO - Job 6: Subtask airbyte_sync_source_dest
[2021-09-03 12:41:38,771] {logging_mixin.py:104} INFO - Running <TaskInstance: cartelis-test.airbyte_sync_source_dest 2021-09-02T00:00:00+00:00 [running]> on host 5249c6c2b9d9
[2021-09-03 12:41:38,946] {taskinstance.py:1302} INFO - Exporting the following env vars:
AIRFLOW_CTX_DAG_EMAIL=***@example.com
AIRFLOW_CTX_DAG_OWNER=***
AIRFLOW_CTX_DAG_ID=cartelis-test
AIRFLOW_CTX_TASK_ID=airbyte_sync_source_dest
AIRFLOW_CTX_EXECUTION_DATE=2021-09-02T00:00:00+00:00
AIRFLOW_CTX_DAG_RUN_ID=scheduled__2021-09-02T00:00:00+00:00
[2021-09-03 12:41:38,967] {taskinstance.py:1501} ERROR - Task failed with exception
Traceback (most recent call last):
  File "/home/airflow/.local/lib/python3.6/site-packages/airflow/models/taskinstance.py", line 1157, in _run_raw_task
    self._prepare_and_execute_task_with_callbacks(context, task)
  File "/home/airflow/.local/lib/python3.6/site-packages/airflow/models/taskinstance.py", line 1331, in _prepare_and_execute_task_with_callbacks
    result = self._execute_task(context, task_copy)
  File "/home/airflow/.local/lib/python3.6/site-packages/airflow/models/taskinstance.py", line 1361, in _execute_task
    result = task_copy.execute(context=context)
  File "/home/airflow/.local/lib/python3.6/site-packages/airflow/providers/airbyte/operators/airbyte.py", line 74, in execute
    job_object = hook.submit_sync_connection(connection_id=self.connection_id)
  File "/home/airflow/.local/lib/python3.6/site-packages/airflow/providers/airbyte/hooks/airbyte.py", line 101, in submit_sync_connection
    headers={"accept": "application/json"},
  File "/home/airflow/.local/lib/python3.6/site-packages/airflow/providers/http/hooks/http.py", line 122, in run
    session = self.get_conn(headers)
  File "/home/airflow/.local/lib/python3.6/site-packages/airflow/providers/http/hooks/http.py", line 72, in get_conn
    conn = self.get_connection(self.http_conn_id)
  File "/home/airflow/.local/lib/python3.6/site-packages/airflow/hooks/base.py", line 67, in get_connection
    conn = Connection.get_connection_from_secrets(conn_id)
  File "/home/airflow/.local/lib/python3.6/site-packages/airflow/models/connection.py", line 379, in get_connection_from_secrets
    raise AirflowNotFoundException(f"The conn_id `{conn_id}` isn't defined")
airflow.exceptions.AirflowNotFoundException: The conn_id `<***_connection_name>` isn't defined
[2021-09-03 12:41:38,972] {taskinstance.py:1551} INFO - Marking task as UP_FOR_RETRY. dag_id=cartelis-test, task_id=airbyte_sync_source_dest, execution_date=20210902T000000, start_date=20210903T124138, end_date=20210903T124138
[2021-09-03 12:41:39,061] {logging_mixin.py:104} WARNING - /home/***/.local/lib/python3.6/site-packages/***/utils/email.py:102 PendingDeprecationWarning: Fetching SMTP credentials from configuration variables will be deprecated in a future release. Please set credentials using a connection instead.
[2021-09-03 12:41:39,062] {configuration.py:365} WARNING - section/key [smtp/smtp_user] not found in config
[2021-09-03 12:41:39,062] {email.py:208} INFO - Email alerting: attempt 1
[2021-09-03 12:41:39,075] {configuration.py:365} WARNING - section/key [smtp/smtp_user] not found in config
[2021-09-03 12:41:39,075] {email.py:208} INFO - Email alerting: attempt 1
[2021-09-03 12:41:39,076] {taskinstance.py:1557} ERROR - Failed to send email to: ['***@example.com']
Traceback (most recent call last):
  File "/home/airflow/.local/lib/python3.6/site-packages/airflow/models/taskinstance.py", line 1157, in _run_raw_task
    self._prepare_and_execute_task_with_callbacks(context, task)
  File "/home/airflow/.local/lib/python3.6/site-packages/airflow/models/taskinstance.py", line 1331, in _prepare_and_execute_task_with_callbacks
    result = self._execute_task(context, task_copy)
  File "/home/airflow/.local/lib/python3.6/site-packages/airflow/models/taskinstance.py", line 1361, in _execute_task
    result = task_copy.execute(context=context)
  File "/home/airflow/.local/lib/python3.6/site-packages/airflow/providers/airbyte/operators/airbyte.py", line 74, in execute
    job_object = hook.submit_sync_connection(connection_id=self.connection_id)
  File "/home/airflow/.local/lib/python3.6/site-packages/airflow/providers/airbyte/hooks/airbyte.py", line 101, in submit_sync_connection
    headers={"accept": "application/json"},
  File "/home/airflow/.local/lib/python3.6/site-packages/airflow/providers/http/hooks/http.py", line 122, in run
    session = self.get_conn(headers)
  File "/home/airflow/.local/lib/python3.6/site-packages/airflow/providers/http/hooks/http.py", line 72, in get_conn
    conn = self.get_connection(self.http_conn_id)
  File "/home/airflow/.local/lib/python3.6/site-packages/airflow/hooks/base.py", line 67, in get_connection
    conn = Connection.get_connection_from_secrets(conn_id)
  File "/home/airflow/.local/lib/python3.6/site-packages/airflow/models/connection.py", line 379, in get_connection_from_secrets
    raise AirflowNotFoundException(f"The conn_id `{conn_id}` isn't defined")
airflow.exceptions.AirflowNotFoundException: The conn_id `<***_connection_name>` isn't defined

During handling of the above exception, another exception occurred:

Traceback (most recent call last):
  File "/home/airflow/.local/lib/python3.6/site-packages/airflow/models/taskinstance.py", line 1896, in email_alert
    send_email(self.task.email, subject, html_content)
  File "/home/airflow/.local/lib/python3.6/site-packages/airflow/utils/email.py", line 66, in send_email
    **kwargs,
  File "/home/airflow/.local/lib/python3.6/site-packages/airflow/utils/email.py", line 102, in send_email_smtp
    send_mime_email(e_from=smtp_mail_from, e_to=recipients, mime_msg=msg, conn_id=conn_id, dryrun=dryrun)
  File "/home/airflow/.local/lib/python3.6/site-packages/airflow/utils/email.py", line 210, in send_mime_email
    conn = _get_smtp_connection(smtp_host, smtp_port, smtp_timeout, smtp_ssl)
  File "/home/airflow/.local/lib/python3.6/site-packages/airflow/utils/email.py", line 244, in _get_smtp_connection
    else smtplib.SMTP(host=host, port=port, timeout=timeout)
  File "/usr/local/lib/python3.6/smtplib.py", line 251, in __init__
    (code, msg) = self.connect(host, port)
  File "/usr/local/lib/python3.6/smtplib.py", line 336, in connect
    self.sock = self._get_socket(host, port, self.timeout)
  File "/usr/local/lib/python3.6/smtplib.py", line 307, in _get_socket
    self.source_address)
  File "/usr/local/lib/python3.6/socket.py", line 724, in create_connection
    raise err
  File "/usr/local/lib/python3.6/socket.py", line 713, in create_connection
    sock.connect(sa)
OSError: [Errno 99] Cannot assign requested address

During handling of the above exception, another exception occurred:

Traceback (most recent call last):
  File "/home/airflow/.local/lib/python3.6/site-packages/airflow/models/taskinstance.py", line 1555, in handle_failure
    self.email_alert(error)
  File "/home/airflow/.local/lib/python3.6/site-packages/airflow/models/taskinstance.py", line 1898, in email_alert
    send_email(self.task.email, subject, html_content_err)
  File "/home/airflow/.local/lib/python3.6/site-packages/airflow/utils/email.py", line 66, in send_email
    **kwargs,
  File "/home/airflow/.local/lib/python3.6/site-packages/airflow/utils/email.py", line 102, in send_email_smtp
    send_mime_email(e_from=smtp_mail_from, e_to=recipients, mime_msg=msg, conn_id=conn_id, dryrun=dryrun)
  File "/home/airflow/.local/lib/python3.6/site-packages/airflow/utils/email.py", line 210, in send_mime_email
    conn = _get_smtp_connection(smtp_host, smtp_port, smtp_timeout, smtp_ssl)
  File "/home/airflow/.local/lib/python3.6/site-packages/airflow/utils/email.py", line 244, in _get_smtp_connection
    else smtplib.SMTP(host=host, port=port, timeout=timeout)
  File "/usr/local/lib/python3.6/smtplib.py", line 251, in __init__
    (code, msg) = self.connect(host, port)
  File "/usr/local/lib/python3.6/smtplib.py", line 336, in connect
    self.sock = self._get_socket(host, port, self.timeout)
  File "/usr/local/lib/python3.6/smtplib.py", line 307, in _get_socket
    self.source_address)
  File "/usr/local/lib/python3.6/socket.py", line 724, in create_connection
    raise err
  File "/usr/local/lib/python3.6/socket.py", line 713, in create_connection
    sock.connect(sa)
OSError: [Errno 99] Cannot assign requested address
[2021-09-03 12:41:39,200] {local_task_job.py:149} INFO - Task exited with return code 1
